Workbook

Sheet Index New
A1: Lexeme | B1: Flexeme | C1: Definition Code | D1: M-W Code | E1: Definition | F1: Notes
A2: 1. Eat | B2: ate ppt | D2: Intransitive
C3: 1(1a) | D3: 1a | E3: To take food or a meal.
C4: 1(2a) | D4: 2a | E4: To affect something by gradual destruction or comsumption. Usually used with 'into', 'away', or 'at'. "The loss was really eating at her." "The controvery ate into his support."
D6: Transitive
C7: 1(3a) | D7: 3a | E7: To take in through the mouth as food. To ingest, chew, and swallow in turn.
C8: 1(4a) | D8: 4a | E8: To destroy, consume, or waste by or as if by eating. "Expenses ate up the profits." "gadgets that eat up too much space"
C9: 1(4b) | D9: 4b | E9: To bear the expense of. To take a loss on. "The team was forced to eat the rest of his contract."
C10: 1(5a) | D10: 5a | E10: To consume gradually. To corrode. "cars eaten away by rust"
C11: 1(5b) | D11: 5b | E11: To consume with vexation. To bother. "What's eating you now?"
C12: 1(6a) | D12: 6a | E12: To enjoy eagerly or avidly. To lap. Usually used with 'up'. "It was an amazing performace and the crowd ate it up.
C13: 1(7a) | D13: 7a | E13: (Usually vulgar) To perform fellatio or cunnilingus on. Often used with 'out'.
C14: 1(8a) | D14: 8a | E14: Phrases: eat it (to fall or be injured) | F14: I added this one.
A16: 2. Begin | B16: began ppt | D16: Intransitive
C17: 2(1a) | D17: 1a | E17: To do the first part of an action. To go into the first part of a process. To start. "Began by introducing herself" "will have to begin again"
C18: 2(2a) | D18: 2a | E18: To come into existence. To arise. "Their problems were just beginning."
C19: 2(2b) | D19: 2b | E19: To have a starting point. "Her career began in Chicago." "Prices begin at $110 per night."
C20: 2(3a) | D20: 3a | E20: To do or succeed in the least degree. "I can't begin to tell you how pleased I am." | F20: This feels transitive to me.
D22: Transitive
C23: 2(4a) | D23: 4a | E23: To set about the activity of. To start. "They began the lecture at 10:00." "have already begun construction"
C24: 2(5a) | D24: 5a | E24: To bring into being. To found. "credited with beginning the movement" "In 1819, he married the daughter of … chief and began a dynasty that would last for nearly 200 years."
C25: 2(5b) | D25: 5b | E25: To originate. To invent. "began their tradition"
A27: 3. Bid | B27: bid pst | D27: Intransitive
B28: bidden ppt | C28: 3(1a) | D28: 1a | E28: To make a bid. "Several other companies bid on the job."
C29: 3(2a) | D29: 2a | E29: Phrase: to bid fair. To seem likely. "a movie that bids fair to become a big hit"
D31: Transitive
C32: 3(3a) | D32: 3a | E32: To offer (a price) whether for payment or acceptance. "The contractor bid $10,000 less than his nearest competitor."
C33: 3(3b) | D33: 3b | E33: Card games: To make a bid of or in (a suit of cards). "bid one spade"
C34: 3(3c) | D34: 3c | E34: To offer. Usually used in the phrase 'to bid defiance'. "The poorest man may in his cottage bid defiance to all the forces of the Crown."
C35: 3(4a) | D35: 4a | E35: To issue an order to. To tell. "did as I was bid" | F35: Overlap between 4a and 4c
C36: 3(4b) | D36: 4b | E36: To request to come. To invite. "were bidden to the wedding"
C37: 3(4c) | D37: 4c | E37: To beseech or entreat. (obsolete)
C38: 3(5a) | D38: 5a | E38: To give expression to. "bade a tearful farewell"
C39: 3(6a) | D39: 6a | E39: Phrase: to bid on | F39: Not in Merriam-Webster
A41: 4. Break | B41: broke ppt | D41: Intransitive
C42: 4(1a) | D42: 1a | E42: To escape with sudden forceful effort. "The attacker broke from the throng."
C43: 4(1b) | D43: 1b | E43: To come into being by or as if by bursting forth. "day was breaking"
C44: 4(1f) | D44: 1f | E44: To become known or published. "when the news broke"
C45: 4(1g) | D45: 1g | E45: To make a sudden dash. "break for cover"
C46: 4(2a) | D46: 2a | E46: To come apart or split into pieces. To fragment. To shatter. "The cup broke when it fell"
...

Sheet Main Data
A1: meaning_index | B1: transitive | C1: intrans_corr_meaning_index | D1: metaphor | E1: iffy | F1: meaning | G1: meaning_notes | H1: lexeme | I1: mps | J1: form | K1: ID | L1: source | M1: text
A2: 1(3a) | B2: 1 | C2: 1 | D2: ? | F2: =_xlfn.XLOOKUP($A:$A,'Index New'!C:C,'Index New'!E:E,"") -> To take in through the mouth as food. To ingest, chew, and swallow in turn. | G2: =_xlfn.LET( _xlpm.r, _xlfn.XLOOKUP(A2,'Index New'!C:C,'Index New'!F:F,""), IF(_xlpm.r=0,"",_xlpm.r) ) | H2: eat | I2: ppt | J2: ate | K2: 3 | L2: Chicago Med | M2: 5186683 What? What? Well, I've ate the biscuits, Did you come to prepare for lessons Dewey. And I took
A3: 1(1a) | F3: =_xlfn.XLOOKUP($A:$A,'Index New'!C:C,'Index New'!E:E,"") -> To take food or a meal. | G3: =_xlfn.LET( _xlpm.r, _xlfn.XLOOKUP(A3,'Index New'!C:C,'Index New'!F:F,""), IF(_xlpm.r=0,"",_xlpm.r) ) | H3: eat | I3: ppt | J3: ate | K3: 4 | L3: Mercy Street | M3: bit. Orderly? Nurse? Yes, soldier? Two days. Haven't ate in two days. Please. Just bring some food. You ain't wearing
A4: 1(7a) | B4: 1 | D4: 1 | F4: =_xlfn.XLOOKUP($A:$A,'Index New'!C:C,'Index New'!E:E,"") -> (Usually vulgar) To perform fellatio or cunnilingus on. Often used with 'out'. | G4: =_xlfn.LET( _xlpm.r, _xlfn.XLOOKUP(A4,'Index New'!C:C,'Index New'!F:F,""), IF(_xlpm.r=0,"",_xlpm.r) ) | H4: eat | I4: ppt | J4: ate | K4: 5 | L4: Survivor's Remorse | M4: , he'll be through. See, my Jupiter like to get his ass ate after brain. And they get the dingleberries and everything. What's a dingleberry
A5: 1(3a) | B5: 1 | C5: 1 | F5: =_xlfn.XLOOKUP($A:$A,'Index New'!C:C,'Index New'!E:E,"") -> To take in through the mouth as food. To ingest, chew, and swallow in turn. | G5: =_xlfn.LET( _xlpm.r, _xlfn.XLOOKUP(A5,'Index New'!C:C,'Index New'!F:F,""), IF(_xlpm.r=0,"",_xlpm.r) ) | H5: eat | I5: ppt | J5: ate | K5: 7 | L5: Clarence | M5: . " Clarence: Did you know they got free cookies? I must have ate, like, two bags' worth. And then this old lady thought that
A6: 1(3a) | B6: 1 | C6: 1 | F6: =_xlfn.XLOOKUP($A:$A,'Index New'!C:C,'Index New'!E:E,"") -> To take in through the mouth as food. To ingest, chew, and swallow in turn. | G6: =_xlfn.LET( _xlpm.r, _xlfn.XLOOKUP(A6,'Index New'!C:C,'Index New'!F:F,""), IF(_xlpm.r=0,"",_xlpm.r) ) | H6: eat | I6: ppt | J6: ate | K6: 8 | L6: Teenage Mutant Ninja... | M6: - [groans] Ugh. Oh, I feel awful. Maybe I shouldn't have ate That jalapeno cappuccino pizza last night. [groans] Huh? [screams] What the - -
A7: 1(1a) | F7: =_xlfn.XLOOKUP($A:$A,'Index New'!C:C,'Index New'!E:E,"") -> To take food or a meal. | G7: =_xlfn.LET( _xlpm.r, _xlfn.XLOOKUP(A7,'Index New'!C:C,'Index New'!F:F,""), IF(_xlpm.r=0,"",_xlpm.r) ) | H7: eat | I7: ppt | J7: ate | K7: 9 | L7: Hell's Kitchen | M7: and home these last three days. And you talking about that you ain't ate? Let's see if there's anything to eat. I'm trying to
A8: 1(3a) | B8: 1 | C8: 1 | F8: =_xlfn.XLOOKUP($A:$A,'Index New'!C:C,'Index New'!E:E,"") -> To take in through the mouth as food. To ingest, chew, and swallow in turn. | G8: =_xlfn.LET( _xlpm.r, _xlfn.XLOOKUP(A8,'Index New'!C:C,'Index New'!F:F,""), IF(_xlpm.r=0,"",_xlpm.r) ) | H8: eat | I8: ppt | J8: ate | K8: 11 | L8: foodnetworkhumor.com | M8: have feelings? They're also living beings. Is it murder when they are ate in a salad? Oh, it's different then no? # Everyone needs
A9: 1(3a) | B9: 1 | C9: 1 | F9: =_xlfn.XLOOKUP($A:$A,'Index New'!C:C,'Index New'!E:E,"") -> To take in through the mouth as food. To ingest, chew, and swallow in turn. | G9: =_xlfn.LET( _xlpm.r, _xlfn.XLOOKUP(A9,'Index New'!C:C,'Index New'!F:F,""), IF(_xlpm.r=0,"",_xlpm.r) ) | H9: eat | I9: ppt | J9: ate | K9: 15 | L9: yelp.com | M9: Zoo deal ($17 for RT lift and buffet breakfast) and wished I had ate breakfast elsewhere. I know what you're thinking it's just breakfast; how
A10: 1(3a) | B10: 1 | C10: 1 | F10: =_xlfn.XLOOKUP($A:$A,'Index New'!C:C,'Index New'!E:E,"") -> To take in through the mouth as food. To ingest, chew, and swallow in turn. | G10: =_xlfn.LET( _xlpm.r, _xlfn.XLOOKUP(A10,'Index New'!C:C,'Index New'!F:F,""), IF(_xlpm.r=0,"",_xlpm.r) ) | H10: eat | I10: ppt | J10: ate | K10: 16 | L10: ...al.library.upenn.edu | M10: face and smelt it, and then said, " This kris good -- has ate a man. " # I could not sleep much, there were such strange
A11: 1(3a) | B11: 1 | C11: 1 | F11: =_xlfn.XLOOKUP($A:$A,'Index New'!C:C,'Index New'!E:E,"") -> To take in through the mouth as food. To ingest, chew, and swallow in turn. | G11: =_xlfn.LET( _xlpm.r, _xlfn.XLOOKUP(A11,'Index New'!C:C,'Index New'!F:F,""), IF(_xlpm.r=0,"",_xlpm.r) ) | H11: eat | I11: ppt | J11: ate | K11: 20 | L11: bible.cc | M11: a religious one; moderation in all ought to be used; and whatever is ate or drank, should be received with thankfulness, and done to the glory of
A12: 1(3a) | B12: 1 | C12: 1 | F12: =_xlfn.XLOOKUP($A:$A,'Index New'!C:C,'Index New'!E:E,"") -> To take in through the mouth as food. To ingest, chew, and swallow in turn. | G12: =_xlfn.LET( _xlpm.r, _xlfn.XLOOKUP(A12,'Index New'!C:C,'Index New'!F:F,""), IF(_xlpm.r=0,"",_xlpm.r) ) | H12: eat | I12: ppt | J12: ate | K12: 25 | L12: kingarthurflour.com | M12: . Elisabeth # We are so doing this! I love the idea and have ate food art that my kids have created that haven't been as cute or appetizing
A13: 1(1a) | F13: =_xlfn.XLOOKUP($A:$A,'Index New'!C:C,'Index New'!E:E,"") -> To take food or a meal. | G13: =_xlfn.LET( _xlpm.r, _xlfn.XLOOKUP(A13,'Index New'!C:C,'Index New'!F:F,""), IF(_xlpm.r=0,"",_xlpm.r) ) | H13: eat | I13: ppt | J13: ate | K13: 31 | L13: answers.yahoo.com | M13: seem to be hungry about an half hour later and feel like I haven't ate all day. My stomach gets a really weird airy feeling like its empty and
A14: 1(3a) | C14: 1 | F14: =_xlfn.XLOOKUP($A:$A,'Index New'!C:C,'Index New'!E:E,"") -> To take in through the mouth as food. To ingest, chew, and swallow in turn. | G14: =_xlfn.LET( _xlpm.r, _xlfn.XLOOKUP(A14,'Index New'!C:C,'Index New'!F:F,""), IF(_xlpm.r=0,"",_xlpm.r) ) | H14: eat | I14: ppt | J14: ate | K14: 36 | L14: eatocracy.cnn.com | M14: us). Whether the woman was pregnant of not, she should not have ate the sandwich while shopping. That would include a parent opening up a package of
A15: 1(3a) | B15: 1 | C15: 1 | F15: =_xlfn.XLOOKUP($A:$A,'Index New'!C:C,'Index New'!E:E,"") -> To take in through the mouth as food. To ingest, chew, and swallow in turn. | G15: =_xlfn.LET( _xlpm.r, _xlfn.XLOOKUP(A15,'Index New'!C:C,'Index New'!F:F,""), IF(_xlpm.r=0,"",_xlpm.r) ) | H15: eat | I15: ppt | J15: ate | K15: 37 | L15: fanfiction.net | M15: room checking the huge computer. # " Aw come on I haven't even ate one pancake! " Beast Boy complained following everyone into the living room. Robin
A16: 1(5b) | B16: 1 | D16: 1 | F16: =_xlfn.XLOOKUP($A:$A,'Index New'!C:C,'Index New'!E:E,"") -> To consume with vexation. To bother. "What's eating you now?" | G16: =_xlfn.LET( _xlpm.r, _xlfn.XLOOKUP(A16,'Index New'!C:C,'Index New'!F:F,""), IF(_xlpm.r=0,"",_xlpm.r) ) | H16: eat | I16: ppt | J16: ate | K16: 38 | L16: tvtropes.org | M16: Bomb of the Year, as Punk called out Laurinaitis for how it must've ate him alive with jealousy that while his brother was one of the legendary Road Warriors
A17: 1(1a) | F17: =_xlfn.XLOOKUP($A:$A,'Index New'!C:C,'Index New'!E:E,"") -> To take food or a meal. | G17: =_xlfn.LET( _xlpm.r, _xlfn.XLOOKUP(A17,'Index New'!C:C,'Index New'!F:F,""), IF(_xlpm.r=0,"",_xlpm.r) ) | H17: eat | I17: ppt | J17: ate | K17: 40 | L17: bible.cc | M17: as do the Jews; that is, he had done so, he had ate with the Gentiles, and as the Gentiles did, without regarding the laws and
A18: 1(7a) | B18: 1 | D18: 1 | F18: =_xlfn.XLOOKUP($A:$A,'Index New'!C:C,'Index New'!E:E,"") -> (Usually vulgar) To perform fellatio or cunnilingus on. Often used with 'out'. | G18: =_xlfn.LET( _xlpm.r, _xlfn.XLOOKUP(A18,'Index New'!C:C,'Index New'!F:F,""), IF(_xlpm.r=0,"",_xlpm.r) ) | H18: eat | I18: ppt | J18: ate | K18: 41 | L18: elyrics.net | M18: Shawty body shaped like a figure eight Yeah that pussy great She bout to get ate # Verse 1: It was a Friday I was on the highway Riding to
A19: 1(3a) | B19: 1 | C19: 1 | F19: =_xlfn.XLOOKUP($A:$A,'Index New'!C:C,'Index New'!E:E,"") -> To take in through the mouth as food. To ingest, chew, and swallow in turn. | G19: =_xlfn.LET( _xlpm.r, _xlfn.XLOOKUP(A19,'Index New'!C:C,'Index New'!F:F,""), IF(_xlpm.r=0,"",_xlpm.r) ) | H19: eat | I19: ppt | J19: ate | K19: 42 | L19: sparkpeople.com | M19: feel SO guilty for going over, BUT, I wonder if I would have ate some protein in the morning, if I would have felt the need to eat
A20: 1(3a) | B20: 1 | C20: 1 | F20: =_xlfn.XLOOKUP($A:$A,'Index New'!C:C,'Index New'!E:E,"") -> To take in through the mouth as food. To ingest, chew, and swallow in turn. | G20: =_xlfn.LET( _xlpm.r, _xlfn.XLOOKUP(A20,'Index New'!C:C,'Index New'!F:F,""), IF(_xlpm.r=0,"",_xlpm.r) ) | H20: eat | I20: ppt | J20: ate | K20: 45 | L20: bible.cc | M20: ; his stomach is empty when he awakes, and he finds he has not ate anything at all: # or as when a thirsty man dreameth, and,
A21: 1(8a) | B21: 1 | D21: 1 | F21: =_xlfn.XLOOKUP($A:$A,'Index New'!C:C,'Index New'!E:E,"") -> Phrases: eat it (to fall or be injured) | G21: =_xlfn.LET( _xlpm.r, _xlfn.XLOOKUP(A21,'Index New'!C:C,'Index New'!F:F,""), IF(_xlpm.r=0,"",_xlpm.r) ) -> I added this one. | H21: eat | I21: ppt | J21: ate | K21: 46 | L21: yelp.com | M21: a fall. I'm scared of stairs though. I'm sure someone has ate it here before, though. And I'm terrified that person will one day
A22: 1(3a) | B22: 1 | C22: 1 | F22: =_xlfn.XLOOKUP($A:$A,'Index New'!C:C,'Index New'!E:E,"") -> To take in through the mouth as food. To ingest, chew, and swallow in turn. | G22: =_xlfn.LET( _xlpm.r, _xlfn.XLOOKUP(A22,'Index New'!C:C,'Index New'!F:F,""), IF(_xlpm.r=0,"",_xlpm.r) ) | H22: eat | I22: ppt | J22: ate | K22: 47 | L22: pitt.edu | M22: . " # Best or worst, " says the girl, " I've ate' em all, and you can't have one till that's come again
A23: 1(3a) | B23: 1 | C23: 1 | D23: ? | F23: =_xlfn.XLOOKUP($A:$A,'Index New'!C:C,'Index New'!E:E,"") -> To take in through the mouth as food. To ingest, chew, and swallow in turn. | G23: =_xlfn.LET( _xlpm.r, _xlfn.XLOOKUP(A23,'Index New'!C:C,'Index New'!F:F,""), IF(_xlpm.r=0,"",_xlpm.r) ) | H23: eat | I23: ppt | J23: ate | K23: 49 | L23: scienceline.org | M23: about it # I am a+ and my body temp. is 96.8 I get ate by a lot of bugs all the time. If I scratch at them,
A24: 1(1a) | F24: =_xlfn.XLOOKUP($A:$A,'Index New'!C:C,'Index New'!E:E,"") -> To take food or a meal. | G24: =_xlfn.LET( _xlpm.r, _xlfn.XLOOKUP(A24,'Index New'!C:C,'Index New'!F:F,""), IF(_xlpm.r=0,"",_xlpm.r) ) | H24: eat | I24: ppt | J24: ate | K24: 50 | L24: huffingtonpost.com | M24: see each other all the time. Plus by 7 o clock everybody should have ate and went home. The only holiday my family celebrate pass 9 is forth of
A25: 1(3a) | B25: 1 | C25: 1 | F25: =_xlfn.XLOOKUP($A:$A,'Index New'!C:C,'Index New'!E:E,"") -> To take in through the mouth as food. To ingest, chew, and swallow in turn. | G25: =_xlfn.LET( _xlpm.r, _xlfn.XLOOKUP(A25,'Index New'!C:C,'Index New'!F:F,""), IF(_xlpm.r=0,"",_xlpm.r) ) | H25: eat | I25: ppt | J25: ate | K25: 52 | L25: literature.org | M25: surveying one small atom of a bone upon the dish), they hadn't ate it all at last! Yet every one had had enough, and the youngest
A26: 1(5a) | B26: 1 | D26: 1 | E26: 1 | F26: =_xlfn.XLOOKUP($A:$A,'Index New'!C:C,'Index New'!E:E,"") -> To consume gradually. To corrode. "cars eaten away by rust" | G26: =_xlfn.LET( _xlpm.r, _xlfn.XLOOKUP(A26,'Index New'!C:C,'Index New'!F:F,""), IF(_xlpm.r=0,"",_xlpm.r) ) | H26: eat | I26: ppt | J26: ate | K26: 53 | L26: etsy.com | M26: priority international. I charge a flat rate that covers the cost. I have ate some $ on a few international orders but just by some change so that's
A27: 1(3a) | B27: 1 | C27: 1 | F27: =_xlfn.XLOOKUP($A:$A,'Index New'!C:C,'Index New'!E:E,"") -> To take in through the mouth as food. To ingest, chew, and swallow in turn. | G27: =_xlfn.LET( _xlpm.r, _xlfn.XLOOKUP(A27,'Index New'!C:C,'Index New'!F:F,""), IF(_xlpm.r=0,"",_xlpm.r) ) | H27: eat | I27: ppt | J27: ate | K27: 54 | L27: ...or.blogs.nytimes.com | M27: Matter of Fashion Tags: # " Much was said, and much was ate, and all went well. " Clearly this sentence was written by a fourth
A28: 1(3a) | B28: 1 | C28: 1 | F28: =_xlfn.XLOOKUP($A:$A,'Index New'!C:C,'Index New'!E:E,"") -> To take in through the mouth as food. To ingest, chew, and swallow in turn. | G28: =_xlfn.LET( _xlpm.r, _xlfn.XLOOKUP(A28,'Index New'!C:C,'Index New'!F:F,""), IF(_xlpm.r=0,"",_xlpm.r) ) | H28: eat | I28: ppt | J28: ate | K28: 55 | L28: ed.msnbc.com | M28: this have to with being president. When Romney was in France he may have ate horse as they do so what? # OO Should be weened off mothers milk
A29: 1(1a) | F29: =_xlfn.XLOOKUP($A:$A,'Index New'!C:C,'Index New'!E:E,"") -> To take food or a meal. | G29: =_xlfn.LET( _xlpm.r, _xlfn.XLOOKUP(A29,'Index New'!C:C,'Index New'!F:F,""), IF(_xlpm.r=0,"",_xlpm.r) ) | H29: eat | I29: ppt | J29: ate | K29: 58 | L29: ...documentaryfilms.com | M29: we act as if it was? # don't judge someone until they've ate good. don't even judge then, you don't know if they are
A30: 1(3a) | B30: 1 | C30: 1 | F30: =_xlfn.XLOOKUP($A:$A,'Index New'!C:C,'Index New'!E:E,"") -> To take in through the mouth as food. To ingest, chew, and swallow in turn. | G30: =_xlfn.LET( _xlpm.r, _xlfn.XLOOKUP(A30,'Index New'!C:C,'Index New'!F:F,""), IF(_xlpm.r=0,"",_xlpm.r) ) | H30: eat | I30: ppt | J30: ate | K30: 60 | L30: asianfanfics.com | M30: # pshinyeong-som on says: Shinyeong happily swallowed the ice cream. She hasn't ate it for years now. She loved the taste of the ice cream. "
A31: 1(3a) | B31: 1 | C31: 1 | F31: =_xlfn.XLOOKUP($A:$A,'Index New'!C:C,'Index New'!E:E,"") -> To take in through the mouth as food. To ingest, chew, and swallow in turn. | G31: =_xlfn.LET( _xlpm.r, _xlfn.XLOOKUP(A31,'Index New'!C:C,'Index New'!F:F,""), IF(_xlpm.r=0,"",_xlpm.r) ) | H31: eat | I31: ppt | J31: ate | K31: 61 | L31: mediaite.com | M31: tried to revive his idea of immigration reform, the gNOpigs turned on him and ate him alive. Newt Gingrich had a similar view a bit more recently, and
A32: 1(3a) | B32: 1 | C32: 1 | F32: =_xlfn.XLOOKUP($A:$A,'Index New'!C:C,'Index New'!E:E,"") -> To take in through the mouth as food. To ingest, chew, and swallow in turn. | G32: =_xlfn.LET( _xlpm.r, _xlfn.XLOOKUP(A32,'Index New'!C:C,'Index New'!F:F,""), IF(_xlpm.r=0,"",_xlpm.r) ) | H32: eat | I32: ppt | J32: ate | K32: 63 | L32: ...stcity.posterous.com | M32: Even lived their whole lives wondering what could have been if only they had not ate of the forbidden fruit. Judas Iscariot is living the rest of his eternity in
A33: 1(1a) | F33: =_xlfn.XLOOKUP($A:$A,'Index New'!C:C,'Index New'!E:E,"") -> To take food or a meal. | G33: =_xlfn.LET( _xlpm.r, _xlfn.XLOOKUP(A33,'Index New'!C:C,'Index New'!F:F,""), IF(_xlpm.r=0,"",_xlpm.r) ) | H33: eat | I33: ppt | J33: ate | K33: 65 | L33: ...lthouse.blogspot.com | M33: one came and I got in. Nice cab. Everything spotless. Could have ate off the floor. Black driver. Fer'ner. Accent. Looked muslim, I
A34: 1(3a) | B34: 1 | C34: 1 | F34: =_xlfn.XLOOKUP($A:$A,'Index New'!C:C,'Index New'!E:E,"") -> To take in through the mouth as food. To ingest, chew, and swallow in turn. | G34: =_xlfn.LET( _xlpm.r, _xlfn.XLOOKUP(A34,'Index New'!C:C,'Index New'!F:F,""), IF(_xlpm.r=0,"",_xlpm.r) ) | H34: eat | I34: ppt | J34: ate | K34: 67 | L34: theafwife.com | M34: it was extremely condensed coffee... we are talking I may as well have just ate the grounds. # Like I said, MONDAY morning. I need my freaking
A35: 1(5a) | B35: 1 | D35: 1 | E35: 1 | F35: =_xlfn.XLOOKUP($A:$A,'Index New'!C:C,'Index New'!E:E,"") -> To consume gradually. To corrode. "cars eaten away by rust" | G35: =_xlfn.LET( _xlpm.r, _xlfn.XLOOKUP(A35,'Index New'!C:C,'Index New'!F:F,""), IF(_xlpm.r=0,"",_xlpm.r) ) | H35: eat | I35: ppt | J35: ate | K35: 70 | L35: nakedcapitalism.com | M35: , in an effort to survive when faced with no bailouts etc, would have ate their own and settled these issues amongst themselves. Instead we are left with the
A36: 1(3a) | B36: 1 | C36: 1 | F36: =_xlfn.XLOOKUP($A:$A,'Index New'!C:C,'Index New'!E:E,"") -> To take in through the mouth as food. To ingest, chew, and swallow in turn. | G36: =_xlfn.LET( _xlpm.r, _xlfn.XLOOKUP(A36,'Index New'!C:C,'Index New'!F:F,""), IF(_xlpm.r=0,"",_xlpm.r) ) | H36: eat | I36: ppt | J36: ate | K36: 75 | L36: tortoiseforum.org | M36: 5 days ago and he got shipped to me. Since receiving him he has ate lettuce which he loves I got him eating calcium on Saturday mixed with the lettuce
A37: 1(3a) | B37: 1 | C37: 1 | F37: =_xlfn.XLOOKUP($A:$A,'Index New'!C:C,'Index New'!E:E,"") -> To take in through the mouth as food. To ingest, chew, and swallow in turn. | G37: =_xlfn.LET( _xlpm.r, _xlfn.XLOOKUP(A37,'Index New'!C:C,'Index New'!F:F,""), IF(_xlpm.r=0,"",_xlpm.r) ) | H37: eat | I37: ppt | J37: ate | K37: 76 | L37: tortoiseforum.org | M37: he loves I got him eating calcium on Saturday mixed with the lettuce he has ate blue berries and tomatoes and also cabbage at one point. Yesterday and the day
A38: 1(3a) | B38: 1 | C38: 1 | F38: =_xlfn.XLOOKUP($A:$A,'Index New'!C:C,'Index New'!E:E,"") -> To take in through the mouth as food. To ingest, chew, and swallow in turn. | G38: =_xlfn.LET( _xlpm.r, _xlfn.XLOOKUP(A38,'Index New'!C:C,'Index New'!F:F,""), IF(_xlpm.r=0,"",_xlpm.r) ) | H38: eat | I38: ppt | J38: ate | K38: 81 | L38: everydaymaven.com | M38: lasagna would be the first ever recipe I want to try. We've never ate or tasted lasagna simply because of the quantity of cheese. Kiran
A39: 1(3a) | B39: 1 | C39: 1 | F39: =_xlfn.XLOOKUP($A:$A,'Index New'!C:C,'Index New'!E:E,"") -> To take in through the mouth as food. To ingest, chew, and swallow in turn. | G39: =_xlfn.LET( _xlpm.r, _xlfn.XLOOKUP(A39,'Index New'!C:C,'Index New'!F:F,""), IF(_xlpm.r=0,"",_xlpm.r) ) | H39: eat | I39: ppt | J39: ate | K39: 83 | L39: babyprediction.net | M39: the bigger dog might have been a carrier of a disease or she could have ate something she shouldn't so I advise you to call the vet and ask.
A40: 1(4a) | B40: 1 | C40: 1 | D40: 1 | F40: =_xlfn.XLOOKUP($A:$A,'Index New'!C:C,'Index New'!E:E,"") -> To destroy, consume, or waste by or as if by eating. "Expenses ate up the profits." "gadgets that eat up too much space" | G40: =_xlfn.LET( _xlpm.r, _xlfn.XLOOKUP(A40,'Index New'!C:C,'Index New'!F:F,""), IF(_xlpm.r=0,"",_xlpm.r) ) | H40: eat | I40: ppt | J40: ate | K40: 87 | L40: reason.com (1) | M40: would have come in there thinking he was King/CEO and the bureaucracy would have ate him alive. # Does anyone here think the dynasty issue will hurt Hillary in
...
